Workbook

Sheet Hypothèses
A1: Paramètre | B1: Valeur | C1: Unité | D1: Source / statut
A2: GÉNÉRAL
A3: Indexation annuelle des tarifs | B3: 0.03 | C3: % | D3: Pratique de l'industrie
A4: Ventes terrains 2026 (Pixum) | B4: 791894.29 | C4: $ | D4: Rapport Pixum 2025-09-15 → 2026-09-15
A5: Ventes saisonniers 2026 (Pixum) | B5: 43208.71 | C5: $ | D5: Pixum
A6: Ventes chalets et chambres 2026 (Pixum) | B6: 497722.97 | C6: $ | D6: Pixum
A7: Ventes cabanas 2026 (Pixum) | B7: 199015.63 | C7: $ | D7: Pixum
A8: Restauration 2026 | B8: 100000 | C8: $ | D8: Budget interne, à valider
A9: Activités et concessions 2026 | B9: 96700 | C9: $ | D9: Budget interne, à valider
A10: Part Havana des ventes Coolbox 2026 (après transport) | B10: 76667.15 | C10: $ | D10: AVIS-HAVANA-2026-001
A11: Part Havana des ventes Coolbox, base récurrente (50 % du CA 2026) | B11: 90167.15 | C11: $ | D11: CALCUL-HAVANA 2026
A13: PAR ANNÉE (colonnes B = 2026, C..G = An 1 à An 5) | B13: 2026 | C13: An 1 | D13: An 2 | E13: An 3 | F13: An 4 | G13: An 5
A14: Terrains : facteur d'occupation | B14: 1 | C14: 1 | D14: 1.02 | E14: 1.03 | F14: 1.04 | G14: 1.04 | H14: x | I14: Aucune capacité nouvelle
A15: Contrats saisonniers | B15: 12 | C15: 30 | D15: 45 | E15: 58 | F15: 66 | G15: 70 | H15: contrats | I15: 12 réels en 2026 ; conversion de terrains existants
A16: Chalets : occupation été (184 nuits) | B16: 0 | C16: 0.58 | D16: 0.61 | E16: 0.63 | F16: 0.65 | G16: 0.66 | H16: % | I16: Réel 2026 ≈ 55-60 %
A17: Chalets : occupation hiver (181 nuits) | B17: 0 | C17: 0.12 | D17: 0.18 | E17: 0.22 | F17: 0.24 | G17: 0.25 | H17: % | I17: Hivernisation automne 2027
A18: Chalets : fraction de l'hiver exploitée | B18: 0 | C18: 0.3 | D18: 1 | E18: 1 | F18: 1 | G18: 1 | H18: x | I18: An 1 : nov.-déc.
A19: Villas : occupation été | B19: 0 | C19: 0.5 | D19: 0.55 | E19: 0.6 | F19: 0.63 | G19: 0.65 | H19: % | I19: Direction
A20: Villas : occupation hiver | B20: 0 | C20: 0.1 | D20: 0.16 | E20: 0.2 | F20: 0.21 | G20: 0.22 | H20: % | I20: hyp.
A21: Villas : fraction de l'été exploitée | B21: 0 | C21: 0.5 | D21: 1 | E21: 1 | F21: 1 | G21: 1 | H21: x | I21: Livraison juillet 2027
A22: Hôtel : chambres | B22: 6 | C22: 11.5 | D22: 17 | E22: 17 | F22: 17 | G22: 17 | H22: ch. | I22: 6 jan.-juin 2027, 17 ensuite
A23: Hôtel : occupation annuelle | B23: 0 | C23: 0.35 | D23: 0.42 | E23: 0.48 | F23: 0.52 | G23: 0.55 | H23: % | I23: Sous la moyenne régionale
A24: Cabanas : facteur | B24: 1 | C24: 1 | D24: 1.02 | E24: 1.04 | F24: 1.05 | G24: 1.05 | H24: x
A25: Coolbox grappe A : occupation été | B25: 0 | C25: 0.55 | D25: 0.6 | E25: 0.63 | F25: 0.65 | G25: 0.65 | H25: % | I25: 9 unités existantes : 20 037 $/unité en 2026
A26: Coolbox grappe A : occupation hiver | B26: 0 | C26: 0.2 | D26: 0.27 | E26: 0.32 | F26: 0.34 | G26: 0.35 | H26: % | I26: Données d'hiver du réseau (annexe J)
A27: Coolbox : fraction de l'été An 1 | B27: 0 | C27: 0.8 | D27: 1 | E27: 1 | F27: 1 | G27: 1 | H27: x | I27: Livraison mai 2027
A28: Restauration : % des revenus d'hébergement (sans alcool) | B28: 0 | C28: 0.08 | D28: 0.14 | E28: 0.18 | F28: 0.19 | G28: 0.2 | H28: % | I28: Réel 2026 : 6,5 %
A29: Spectacles : billetterie brute | B29: 0 | C29: 0 | D29: 60000 | E29: 120000 | F29: 150000 | G29: 160000 | H29: $ | I29: Scène et chapiteau existants (hyp.)
A30: Activités et concessions | B30: 96700 | C30: 105000 | D30: 125000 | E30: 140000 | F30: 148000 | G30: 155000 | H30: $ | I30: Budget interne
A31: Salaires : % des revenus | B31: 0.39 | C31: 0.36 | D31: 0.34 | E31: 0.32 | F31: 0.31 | G31: 0.3 | H31: % | I31: Tableau d'effectifs ; Grenier 2021 : 30 %
A32: Énergie | B32: 242500 | C32: 275000 | D32: 400000 | E32: 420000 | F32: 435000 | G32: 450000 | H32: $ | I32: Budget de la direction
A33: Assurances | B33: 60000 | C33: 95000 | D33: 130000 | E33: 134000 | F33: 138000 | G33: 142000 | H33: $
A34: Taxes municipales et scolaires | B34: 54500 | C34: 75000 | D34: 130000 | E34: 133000 | F34: 136000 | G34: 139000 | H34: $ | I34: Rôle 2024-2026
A35: Marketing : % des revenus | B35: 0.03 | C35: 0.035 | D35: 0.035 | E35: 0.03 | F35: 0.03 | G35: 0.03 | H35: %
A37: TARIFS ET UNITÉS
A38: Chalets (unités) | B38: 16 | C38: u | D38: Inventaire
A39: Tarif chalet été | B39: 235 | C39: $ | D39: Tarif 2026
A40: Tarif chalet hiver | B40: 210 | C40: $ | D40: hyp.
A41: Villas (unités) | B41: 13 | C41: u
A42: Tarif villa été | B42: 275 | C42: $ | D42: Direction
...

Sheet Investissement
A1: Emploi | B1: Montant | C1: Statut
A2: Projets de développement, phase 1a (hôtel, restaurant, villas, chalets, grappe Coolbox, saisonniers) | B2: 2859800
A3: Contingence (5 % forfaits d'usine, 10 % travaux de chantier) | B3: 235490
A4: Honoraires professionnels (plans, ingénierie, permis) | B4: 175000
A5: Mise en conformité environnementale et réglementaire (hyp.) | B5: 250000
A6: Intérêts capitalisés pendant la construction (hyp.) | B6: 52500
A7: Réserve de service de la dette (6 mois, déposée à la clôture) | B7: 233237
A8: Frais de financement et juridiques (montage multi-bailleurs) | B8: 125000
A9: Fonds de roulement de démarrage | B9: 250000
A10: Refinancement de la dette existante (selon relevés des créanciers, hyp.) | B10: 4000000
A11: Total des emplois | B11: =SUM(B2:B10) -> 8181027
A13: Source | B13: Montant | C13: Taux | D13: Amortissement (ans) | E13: Moratoire (mois) | F13: Statut
A14: Prêt hypothécaire de premier rang (tranche A refinancement, tranche B construction) | B14: 5500000 | C14: 0.07 | D14: 25 | E14: 12 | F14: Demandé
A15: DEC – contribution remboursable sans intérêt (hyp.) | B15: 500000 | C15: 0 | D15: 7 | E15: 24 | F15: À solliciter
A16: Quasi-équité patiente : Fonds régional de solidarité FTQ Estrie ou Fondaction (hyp.) | B16: 750000 | C16: 0.09 | D16: 7 | E16: 36 | F16: À solliciter
A17: MRC du Val-Saint-François – FLI / FLS (hyp.) | B17: 150000 | C17: 0.06 | D17: 7 | E17: 12 | F17: À solliciter
A18: Construction Prospère – retenue contractuelle subordonnée (10 % des travaux de chantier) | B18: 185000 | C18: 0.05 | D18: 5 | E18: 24 | F18: Engagé (à signer)
A19: Fonds propres (= emplois − couches de dette) | B19: =Investissement!$B$11-SUM(B14:B18) -> 1096027
A20: Total des sources | B20: =SUM(B14:B19) -> 8181027
A21: Argent neuf (emplois hors refinancement) | B21: =Investissement!$B$11-B10 -> 4181027
A22: Fonds propres / argent neuf | B22: =Investissement!$B$19/Investissement!$B$21 -> 0.26214301

Sheet Dette
A1: Prêt hypothécaire de premier rang (tranche A refinancement, tranche B construction)
A2: Montant | B2: =Investissement!B14 -> 5500000 | C2: Taux | D2: =Investissement!C14 -> 0.07 | E2: Amort. (ans) | F2: =Investissement!D14 -> 25 | G2: Moratoire (mois) | H2: =Investissement!E14 -> 12 | I2: Paiement mensuel | J2: =IF(D2=0,B2/(F2*12),PMT(D2/12,F2*12,-B2)) -> 38872.856
A3: Mois | B3: Solde début | C3: Intérêts | D3: Capital | E3: Paiement | F3: Solde fin
A4: 1 | B4: =B2 -> 5500000 | C4: =B4*D$2/12*1 -> 32083.333 | D4: =IF(A4<=H$2,0,MIN(B4,IF(D$2=0,J$2,J$2-B4*D$2/12))) -> 0 | E4: =C4+D4 -> 32083.333 | F4: =B4-D4 -> 5500000
A5: 2 | B5: =F4 -> 5500000 | C5: =B5*D$2/12*1 -> 32083.333 | D5: =IF(A5<=H$2,0,MIN(B5,IF(D$2=0,J$2,J$2-B5*D$2/12))) -> 0 | E5: =C5+D5 -> 32083.333 | F5: =B5-D5 -> 5500000
A6: 3 | B6: =F5 -> 5500000 | C6: =B6*D$2/12*1 -> 32083.333 | D6: =IF(A6<=H$2,0,MIN(B6,IF(D$2=0,J$2,J$2-B6*D$2/12))) -> 0 | E6: =C6+D6 -> 32083.333 | F6: =B6-D6 -> 5500000
A7: 4 | B7: =F6 -> 5500000 | C7: =B7*D$2/12*1 -> 32083.333 | D7: =IF(A7<=H$2,0,MIN(B7,IF(D$2=0,J$2,J$2-B7*D$2/12))) -> 0 | E7: =C7+D7 -> 32083.333 | F7: =B7-D7 -> 5500000
A8: 5 | B8: =F7 -> 5500000 | C8: =B8*D$2/12*1 -> 32083.333 | D8: =IF(A8<=H$2,0,MIN(B8,IF(D$2=0,J$2,J$2-B8*D$2/12))) -> 0 | E8: =C8+D8 -> 32083.333 | F8: =B8-D8 -> 5500000
A9: 6 | B9: =F8 -> 5500000 | C9: =B9*D$2/12*1 -> 32083.333 | D9: =IF(A9<=H$2,0,MIN(B9,IF(D$2=0,J$2,J$2-B9*D$2/12))) -> 0 | E9: =C9+D9 -> 32083.333 | F9: =B9-D9 -> 5500000
A10: 7 | B10: =F9 -> 5500000 | C10: =B10*D$2/12*1 -> 32083.333 | D10: =IF(A10<=H$2,0,MIN(B10,IF(D$2=0,J$2,J$2-B10*D$2/12))) -> 0 | E10: =C10+D10 -> 32083.333 | F10: =B10-D10 -> 5500000
A11: 8 | B11: =F10 -> 5500000 | C11: =B11*D$2/12*1 -> 32083.333 | D11: =IF(A11<=H$2,0,MIN(B11,IF(D$2=0,J$2,J$2-B11*D$2/12))) -> 0 | E11: =C11+D11 -> 32083.333 | F11: =B11-D11 -> 5500000
A12: 9 | B12: =F11 -> 5500000 | C12: =B12*D$2/12*1 -> 32083.333 | D12: =IF(A12<=H$2,0,MIN(B12,IF(D$2=0,J$2,J$2-B12*D$2/12))) -> 0 | E12: =C12+D12 -> 32083.333 | F12: =B12-D12 -> 5500000
A13: 10 | B13: =F12 -> 5500000 | C13: =B13*D$2/12*1 -> 32083.333 | D13: =IF(A13<=H$2,0,MIN(B13,IF(D$2=0,J$2,J$2-B13*D$2/12))) -> 0 | E13: =C13+D13 -> 32083.333 | F13: =B13-D13 -> 5500000
A14: 11 | B14: =F13 -> 5500000 | C14: =B14*D$2/12*1 -> 32083.333 | D14: =IF(A14<=H$2,0,MIN(B14,IF(D$2=0,J$2,J$2-B14*D$2/12))) -> 0 | E14: =C14+D14 -> 32083.333 | F14: =B14-D14 -> 5500000
A15: 12 | B15: =F14 -> 5500000 | C15: =B15*D$2/12*1 -> 32083.333 | D15: =IF(A15<=H$2,0,MIN(B15,IF(D$2=0,J$2,J$2-B15*D$2/12))) -> 0 | E15: =C15+D15 -> 32083.333 | F15: =B15-D15 -> 5500000
A16: 13 | B16: =F15 -> 5500000 | C16: =B16*D$2/12 -> 32083.333 | D16: =IF(A16<=H$2,0,MIN(B16,IF(D$2=0,J$2,J$2-B16*D$2/12))) -> 6789.5225 | E16: =C16+D16 -> 38872.856 | F16: =B16-D16 -> 5493210.5
A17: 14 | B17: =F16 -> 5493210.5 | C17: =B17*D$2/12 -> 32043.728 | D17: =IF(A17<=H$2,0,MIN(B17,IF(D$2=0,J$2,J$2-B17*D$2/12))) -> 6829.1281 | E17: =C17+D17 -> 38872.856 | F17: =B17-D17 -> 5486381.3
A18: 15 | B18: =F17 -> 5486381.3 | C18: =B18*D$2/12 -> 32003.891 | D18: =IF(A18<=H$2,0,MIN(B18,IF(D$2=0,J$2,J$2-B18*D$2/12))) -> 6868.9646 | E18: =C18+D18 -> 38872.856 | F18: =B18-D18 -> 5479512.4
A19: 16 | B19: =F18 -> 5479512.4 | C19: =B19*D$2/12 -> 31963.822 | D19: =IF(A19<=H$2,0,MIN(B19,IF(D$2=0,J$2,J$2-B19*D$2/12))) -> 6909.0336 | E19: =C19+D19 -> 38872.856 | F19: =B19-D19 -> 5472603.4
A20: 17 | B20: =F19 -> 5472603.4 | C20: =B20*D$2/12 -> 31923.52 | D20: =IF(A20<=H$2,0,MIN(B20,IF(D$2=0,J$2,J$2-B20*D$2/12))) -> 6949.3363 | E20: =C20+D20 -> 38872.856 | F20: =B20-D20 -> 5465654
A21: 18 | B21: =F20 -> 5465654 | C21: =B21*D$2/12 -> 31882.982 | D21: =IF(A21<=H$2,0,MIN(B21,IF(D$2=0,J$2,J$2-B21*D$2/12))) -> 6989.8741 | E21: =C21+D21 -> 38872.856 | F21: =B21-D21 -> 5458664.1
A22: 19 | B22: =F21 -> 5458664.1 | C22: =B22*D$2/12 -> 31842.207 | D22: =IF(A22<=H$2,0,MIN(B22,IF(D$2=0,J$2,J$2-B22*D$2/12))) -> 7030.6484 | E22: =C22+D22 -> 38872.856 | F22: =B22-D22 -> 5451633.5
A23: 20 | B23: =F22 -> 5451633.5 | C23: =B23*D$2/12 -> 31801.195 | D23: =IF(A23<=H$2,0,MIN(B23,IF(D$2=0,J$2,J$2-B23*D$2/12))) -> 7071.6605 | E23: =C23+D23 -> 38872.856 | F23: =B23-D23 -> 5444561.8
A24: 21 | B24: =F23 -> 5444561.8 | C24: =B24*D$2/12 -> 31759.944 | D24: =IF(A24<=H$2,0,MIN(B24,IF(D$2=0,J$2,J$2-B24*D$2/12))) -> 7112.9118 | E24: =C24+D24 -> 38872.856 | F24: =B24-D24 -> 5437448.9
A25: 22 | B25: =F24 -> 5437448.9 | C25: =B25*D$2/12 -> 31718.452 | D25: =IF(A25<=H$2,0,MIN(B25,IF(D$2=0,J$2,J$2-B25*D$2/12))) -> 7154.4038 | E25: =C25+D25 -> 38872.856 | F25: =B25-D25 -> 5430294.5
A26: 23 | B26: =F25 -> 5430294.5 | C26: =B26*D$2/12 -> 31676.718 | D26: =IF(A26<=H$2,0,MIN(B26,IF(D$2=0,J$2,J$2-B26*D$2/12))) -> 7196.1378 | E26: =C26+D26 -> 38872.856 | F26: =B26-D26 -> 5423098.4
A27: 24 | B27: =F26 -> 5423098.4 | C27: =B27*D$2/12 -> 31634.741 | D27: =IF(A27<=H$2,0,MIN(B27,IF(D$2=0,J$2,J$2-B27*D$2/12))) -> 7238.1153 | E27: =C27+D27 -> 38872.856 | F27: =B27-D27 -> 5415860.3
... A63: 60 | B63: =F62 -> 5134079.7 | C63: =B63*D$2/12 -> 29948.798 | D63: =IF(A63<=H$2,0,MIN(B63,IF(D$2=0,J$2,J$2-B63*D$2/12))) -> 8924.0576 | E63: =C63+D63 -> 38872.856 | F63: =B63-D63 -> 5125155.6
A64: Année | B64: Intérêts | C64: Capital | D64: Service | E64: Solde fin
A65: An 1 | B65: =SUM(C4:C15) -> 385000 | C65: =SUM(D4:D15) -> 0 | D65: =B65+C65 -> 385000 | E65: =F15 -> 5500000
A66: An 2 | B66: =SUM(C16:C27) -> 382334.53 | C66: =SUM(D16:D27) -> 84139.737 | D66: =B66+C66 -> 466474.27 | E66: =F27 -> 5415860.3
A67: An 3 | B67: =SUM(C28:C39) -> 376252.06 | C67: =SUM(D28:D39) -> 90222.205 | D67: =B67+C67 -> 466474.27 | E67: =F39 -> 5325638.1
A68: An 4 | B68: =SUM(C40:C51) -> 369729.89 | C68: =SUM(D40:D51) -> 96744.376 | D68: =B68+C68 -> 466474.27 | E68: =F51 -> 5228893.7
A69: An 5 | B69: =SUM(C52:C63) -> 362736.24 | C69: =SUM(D52:D63) -> 103738.03 | D69: =B69+C69 -> 466474.27 | E69: =F63 -> 5125155.6
A71: DEC – contribution remboursable sans intérêt (hyp.)
A72: Montant | B72: =Investissement!B15 -> 500000 | C72: Taux | D72: =Investissement!C15 -> 0 | E72: Amort. (ans) | F72: =Investissement!D15 -> 7 | G72: Moratoire (mois) | H72: =Investissement!E15 -> 24 | I72: Paiement mensuel | J72: =IF(D72=0,B72/(F72*12),PMT(D72/12,F72*12,-B72)) -> 5952.381
A73: Mois | B73: Solde début | C73: Intérêts | D73: Capital | E73: Paiement | F73: Solde fin
A74: 1 | B74: =B72 -> 500000 | C74: =B74*D$72/12 -> 0 | D74: =IF(A74<=H$72,0,MIN(B74,IF(D$72=0,J$72,J$72-B74*D$72/12))) -> 0 | E74: =C74+D74 -> 0 | F74: =B74-D74 -> 500000
A75: 2 | B75: =F74 -> 500000 | C75: =B75*D$72/12 -> 0 | D75: =IF(A75<=H$72,0,MIN(B75,IF(D$72=0,J$72,J$72-B75*D$72/12))) -> 0 | E75: =C75+D75 -> 0 | F75: =B75-D75 -> 500000
A76: 3 | B76: =F75 -> 500000 | C76: =B76*D$72/12 -> 0 | D76: =IF(A76<=H$72,0,MIN(B76,IF(D$72=0,J$72,J$72-B76*D$72/12))) -> 0 | E76: =C76+D76 -> 0 | F76: =B76-D76 -> 500000
...

Sheet Résultats
B1: 2026 | C1: An 1 | D1: An 2 | E1: An 3 | F1: An 4 | G1: An 5
A2: REVENUS
A3: Terrains de camping | B3: =Hypothèses!$B$4 -> 791894.29 | C3: =Hypothèses!$B$4*(1+Hypothèses!$B$3)^1*Hypothèses!$C$14 -> 815651.12 | D3: =Hypothèses!$B$4*(1+Hypothèses!$B$3)^2*Hypothèses!$D$14 -> 856923.07 | E3: =Hypothèses!$B$4*(1+Hypothèses!$B$3)^3*Hypothèses!$E$14 -> 891284 | F3: =Hypothèses!$B$4*(1+Hypothèses!$B$3)^4*Hypothèses!$F$14 -> 926935.36 | G3: =Hypothèses!$B$4*(1+Hypothèses!$B$3)^5*Hypothèses!$G$14 -> 954743.42
A4: Terrains saisonniers | B4: =Hypothèses!$B$5 -> 43208.71 | C4: =Hypothèses!$C$15*Hypothèses!$B$48*(1+Hypothèses!$B$3)^0 -> 109500 | D4: =Hypothèses!$D$15*Hypothèses!$B$48*(1+Hypothèses!$B$3)^1 -> 169177.5 | E4: =Hypothèses!$E$15*Hypothèses!$B$48*(1+Hypothèses!$B$3)^2 -> 224592.53 | F4: =Hypothèses!$F$15*Hypothèses!$B$48*(1+Hypothèses!$B$3)^3 -> 263237.93 | G4: =Hypothèses!$G$15*Hypothèses!$B$48*(1+Hypothèses!$B$3)^4 -> 287567.5
A5: Chalets 4 saisons (16) | B5: =Hypothèses!$B$6 -> 497722.97 | C5: =Hypothèses!$B$38*(184*Hypothèses!$C$16*Hypothèses!$B$39*(1+Hypothèses!$B$3)^0+181*Hypothèses!$C$18*Hypothèses!$C$17*Hypothèses!$B$40*(1+Hypothèses!$B$3)^0) -> 423160.96 | D5: =Hypothèses!$B$38*(184*Hypothèses!$D$16*Hypothèses!$B$39*(1+Hypothèses!$B$3)^1+181*Hypothèses!$D$18*Hypothèses!$D$17*Hypothèses!$B$40*(1+Hypothèses!$B$3)^1) -> 547435.94 | E5: =Hypothèses!$B$38*(184*Hypothèses!$E$16*Hypothèses!$B$39*(1+Hypothèses!$B$3)^2+181*Hypothèses!$E$18*Hypothèses!$E$17*Hypothèses!$B$40*(1+Hypothèses!$B$3)^2) -> 604346.35 | F5: =Hypothèses!$B$38*(184*Hypothèses!$F$16*Hypothèses!$B$39*(1+Hypothèses!$B$3)^3+181*Hypothèses!$F$18*Hypothèses!$F$17*Hypothèses!$B$40*(1+Hypothèses!$B$3)^3) -> 650887.65 | G5: =Hypothèses!$B$38*(184*Hypothèses!$G$16*Hypothèses!$B$39*(1+Hypothèses!$B$3)^4+181*Hypothèses!$G$18*Hypothèses!$G$17*Hypothèses!$B$40*(1+Hypothèses!$B$3)^4) -> 685045.89
A6: Villas (13) | B6: =0 -> 0 | C6: =Hypothèses!$B$41*(184*Hypothèses!$C$21*Hypothèses!$C$19*Hypothèses!$B$42*(1+Hypothèses!$B$3)^0+181*Hypothèses!$C$20*Hypothèses!$B$43*(1+Hypothèses!$B$3)^0) -> 222098.5 | D6: =Hypothèses!$B$41*(184*Hypothèses!$D$21*Hypothèses!$D$19*Hypothèses!$B$42*(1+Hypothèses!$B$3)^1+181*Hypothèses!$D$20*Hypothèses!$B$43*(1+Hypothèses!$B$3)^1) -> 467648.43 | E6: =Hypothèses!$B$41*(184*Hypothèses!$E$21*Hypothèses!$E$19*Hypothèses!$B$42*(1+Hypothèses!$B$3)^2+181*Hypothèses!$E$20*Hypothèses!$B$43*(1+Hypothèses!$B$3)^2) -> 541034.6 | F6: =Hypothèses!$B$41*(184*Hypothèses!$F$21*Hypothèses!$F$19*Hypothèses!$B$42*(1+Hypothèses!$B$3)^3+181*Hypothèses!$F$20*Hypothèses!$B$43*(1+Hypothèses!$B$3)^3) -> 585128.92 | G6: =Hypothèses!$B$41*(184*Hypothèses!$G$21*Hypothèses!$G$19*Hypothèses!$B$42*(1+Hypothèses!$B$3)^4+181*Hypothèses!$G$20*Hypothèses!$B$43*(1+Hypothèses!$B$3)^4) -> 623978.37
A7: Hôtel (6 → 17 chambres) | B7: =0 -> 0 | C7: =Hypothèses!$C$22*365*Hypothèses!$C$23*Hypothèses!$B$44*(1+Hypothèses!$B$3)^0 -> 279133.75 | D7: =Hypothèses!$D$22*365*Hypothèses!$D$23*Hypothèses!$B$44*(1+Hypothèses!$B$3)^1 -> 510013.77 | E7: =Hypothèses!$E$22*365*Hypothèses!$E$23*Hypothèses!$B$44*(1+Hypothèses!$B$3)^2 -> 600359.07 | F7: =Hypothèses!$F$22*365*Hypothèses!$F$23*Hypothèses!$B$44*(1+Hypothèses!$B$3)^3 -> 669900.66 | G7: =Hypothèses!$G$22*365*Hypothèses!$G$23*Hypothèses!$B$44*(1+Hypothèses!$B$3)^4 -> 729805.24
A8: Cabanas (13) | B8: =Hypothèses!$B$7 -> 199015.63 | C8: =Hypothèses!$B$7*(1+Hypothèses!$B$3)^1*Hypothèses!$C$24 -> 204986.1 | D8: =Hypothèses!$B$7*(1+Hypothèses!$B$3)^2*Hypothèses!$D$24 -> 215358.4 | E8: =Hypothèses!$B$7*(1+Hypothèses!$B$3)^3*Hypothèses!$E$24 -> 226168.54 | F8: =Hypothèses!$B$7*(1+Hypothèses!$B$3)^4*Hypothèses!$F$24 -> 235193.54 | G8: =Hypothèses!$B$7*(1+Hypothèses!$B$3)^5*Hypothèses!$G$24 -> 242249.34
A9: Unités Coolbox grappe A (9, propriété Havana) | B9: =0 -> 0 | C9: =Hypothèses!$B$45*(184*Hypothèses!$C$27*Hypothèses!$C$25*Hypothèses!$B$46*(1+Hypothèses!$B$3)^0+181*Hypothèses!$C$26*Hypothèses!$B$47*(1+Hypothèses!$B$3)^0) -> 228778.2 | D9: =Hypothèses!$B$45*(184*Hypothèses!$D$27*Hypothèses!$D$25*Hypothèses!$B$46*(1+Hypothèses!$B$3)^1+181*Hypothèses!$D$26*Hypothèses!$B$47*(1+Hypothèses!$B$3)^1) -> 320418.76 | E9: =Hypothèses!$B$45*(184*Hypothèses!$E$27*Hypothèses!$E$25*Hypothèses!$B$46*(1+Hypothèses!$B$3)^2+181*Hypothèses!$E$26*Hypothèses!$B$47*(1+Hypothèses!$B$3)^2) -> 359085.71 | F9: =Hypothèses!$B$45*(184*Hypothèses!$F$27*Hypothèses!$F$25*Hypothèses!$B$46*(1+Hypothèses!$B$3)^3+181*Hypothèses!$F$26*Hypothèses!$B$47*(1+Hypothèses!$B$3)^3) -> 385085.89 | G9: =Hypothèses!$B$45*(184*Hypothèses!$G$27*Hypothèses!$G$25*Hypothèses!$B$46*(1+Hypothèses!$B$3)^4+181*Hypothèses!$G$26*Hypothèses!$B$47*(1+Hypothèses!$B$3)^4) -> 400287.04
A10: Partenariat Coolbox HPA, part Havana | B10: =Hypothèses!$B$10 -> 76667.15 | C10: =Hypothèses!$B$11*(1+Hypothèses!$B$3)^1 -> 92872.164 | D10: =Hypothèses!$B$11*(1+Hypothèses!$B$3)^2 -> 95658.329 | E10: =Hypothèses!$B$11*(1+Hypothèses!$B$3)^3 -> 98528.079 | F10: =Hypothèses!$B$11*(1+Hypothèses!$B$3)^4 -> 101483.92 | G10: =Hypothèses!$B$11*(1+Hypothèses!$B$3)^5 -> 104528.44
A11: Restauration (sans alcool) | B11: =Hypothèses!$B$8 -> 100000 | C11: =SUM(C3:C9)*Hypothèses!$C$28 -> 182664.69 | D11: =SUM(D3:D9)*Hypothèses!$D$28 -> 432176.62 | E11: =SUM(E3:E9)*Hypothèses!$E$28 -> 620436.74 | F11: =SUM(F3:F9)*Hypothèses!$F$28 -> 706110.29 | G11: =SUM(G3:G9)*Hypothèses!$G$28 -> 784735.36
A12: Spectacles (billetterie brute) | B12: =Hypothèses!$B$29*(1+Hypothèses!$B$3)^MAX(0-2,0) -> 0 | C12: =Hypothèses!$C$29*(1+Hypothèses!$B$3)^MAX(1-2,0) -> 0 | D12: =Hypothèses!$D$29*(1+Hypothèses!$B$3)^MAX(2-2,0) -> 60000 | E12: =Hypothèses!$E$29*(1+Hypothèses!$B$3)^MAX(3-2,0) -> 123600 | F12: =Hypothèses!$F$29*(1+Hypothèses!$B$3)^MAX(4-2,0) -> 159135 | G12: =Hypothèses!$G$29*(1+Hypothèses!$B$3)^MAX(5-2,0) -> 174836.32
A13: Activités et concessions | B13: =Hypothèses!$B$30 -> 96700 | C13: =Hypothèses!$C$30 -> 105000 | D13: =Hypothèses!$D$30 -> 125000 | E13: =Hypothèses!$E$30 -> 140000 | F13: =Hypothèses!$F$30 -> 148000 | G13: =Hypothèses!$G$30 -> 155000
A14: Total des revenus (× facteur de scénario) | B14: =SUM(B3:B13)*Hypothèses!$B$87 -> 1805208.8 | C14: =SUM(C3:C13)*Hypothèses!$B$87 -> 2663845.5 | D14: =SUM(D3:D13)*Hypothèses!$B$87 -> 3799810.8 | E14: =SUM(E3:E13)*Hypothèses!$B$87 -> 4429435.6 | F14: =SUM(F3:F13)*Hypothèses!$B$87 -> 4831099.2 | G14: =SUM(G3:G13)*Hypothèses!$B$87 -> 5142776.9
A16: CHARGES
A17: Coût des ventes | B17: =(B11*Hypothèses!$B$52+B13*Hypothèses!$B$53)*Hypothèses!$B$87 -> 52340 | C17: =(C11*Hypothèses!$B$52+C13*Hypothèses!$B$53)*Hypothèses!$B$87 -> 81279.348 | D17: =(D11*Hypothèses!$B$52+D13*Hypothèses!$B$53)*Hypothèses!$B$87 -> 167618.28 | E17: =(E11*Hypothèses!$B$52+E13*Hypothèses!$B$53)*Hypothèses!$B$87 -> 232744.13 | F17: =(F11*Hypothèses!$B$52+F13*Hypothèses!$B$53)*Hypothèses!$B$87 -> 262616.4 | G17: =(G11*Hypothèses!$B$52+G13*Hypothèses!$B$53)*Hypothèses!$B$87 -> 289962.67
A18: Cachets et technique des spectacles | B18: =B12*Hypothèses!$B$54*Hypothèses!$B$87 -> 0 | C18: =C12*Hypothèses!$B$54*Hypothèses!$B$87 -> 0 | D18: =D12*Hypothèses!$B$54*Hypothèses!$B$87 -> 33000 | E18: =E12*Hypothèses!$B$54*Hypothèses!$B$87 -> 67980 | F18: =F12*Hypothèses!$B$54*Hypothèses!$B$87 -> 87524.25 | G18: =G12*Hypothèses!$B$54*Hypothèses!$B$87 -> 96159.976
A19: Commissions de plateformes | B19: =(B7+B6+B9)*Hypothèses!$B$55*Hypothèses!$B$87 -> 0 | C19: =(C7+C6+C9)*Hypothèses!$B$55*Hypothèses!$B$87 -> 43800.627 | D19: =(D7+D6+D9)*Hypothèses!$B$55*Hypothèses!$B$87 -> 77884.857 | E19: =(E7+E6+E9)*Hypothèses!$B$55*Hypothèses!$B$87 -> 90028.762 | F19: =(F7+F6+F9)*Hypothèses!$B$55*Hypothèses!$B$87 -> 98406.928 | G19: =(G7+G6+G9)*Hypothèses!$B$55*Hypothèses!$B$87 -> 105244.24
A20: Salaires et charges sociales | B20: =B$14*Hypothèses!$B$31 -> 704031.41 | C20: =C$14*Hypothèses!$C$31 -> 958984.37 | D20: =D$14*Hypothèses!$D$31 -> 1291935.7 | E20: =E$14*Hypothèses!$E$31 -> 1417419.4 | F20: =F$14*Hypothèses!$F$31 -> 1497640.7 | G20: =G$14*Hypothèses!$G$31 -> 1542833.1
A21: Électricité, chauffage et propane | B21: =Hypothèses!$B$32 -> 242500 | C21: =Hypothèses!$C$32 -> 275000 | D21: =Hypothèses!$D$32 -> 400000 | E21: =Hypothèses!$E$32 -> 420000 | F21: =Hypothèses!$F$32 -> 435000 | G21: =Hypothèses!$G$32 -> 450000
A22: Entretien et réparations | B22: =B$14*Hypothèses!$B$56 -> 144416.7 | C22: =C$14*Hypothèses!$B$56 -> 213107.64 | D22: =D$14*Hypothèses!$B$56 -> 303984.86 | E22: =E$14*Hypothèses!$B$56 -> 354354.85 | F22: =F$14*Hypothèses!$B$56 -> 386487.93 | G22: =G$14*Hypothèses!$B$56 -> 411422.15
A23: Véhicules et essence | B23: =Hypothèses!$B$58*(1+Hypothèses!$B$3)^0 -> 88500 | C23: =Hypothèses!$B$58*(1+Hypothèses!$B$3)^1 -> 91155 | D23: =Hypothèses!$B$58*(1+Hypothèses!$B$3)^2 -> 93889.65 | E23: =Hypothèses!$B$58*(1+Hypothèses!$B$3)^3 -> 96706.34 | F23: =Hypothèses!$B$58*(1+Hypothèses!$B$3)^4 -> 99607.53 | G23: =Hypothèses!$B$58*(1+Hypothèses!$B$3)^5 -> 102595.76
A24: Marketing | B24: =B$14*Hypothèses!$B$35 -> 54156.262 | C24: =C$14*Hypothèses!$C$35 -> 93234.592 | D24: =D$14*Hypothèses!$D$35 -> 132993.38 | E24: =E$14*Hypothèses!$E$35 -> 132883.07 | F24: =F$14*Hypothèses!$F$35 -> 144932.97 | G24: =G$14*Hypothèses!$G$35 -> 154283.31
A25: Assurances | B25: =Hypothèses!$B$33 -> 60000 | C25: =Hypothèses!$C$33 -> 95000 | D25: =Hypothèses!$D$33 -> 130000 | E25: =Hypothèses!$E$33 -> 134000 | F25: =Hypothèses!$F$33 -> 138000 | G25: =Hypothèses!$G$33 -> 142000
A26: Taxes municipales et scolaires | B26: =Hypothèses!$B$34 -> 54500 | C26: =Hypothèses!$C$34 -> 75000 | D26: =Hypothèses!$D$34 -> 130000 | E26: =Hypothèses!$E$34 -> 133000 | F26: =Hypothèses!$F$34 -> 136000 | G26: =Hypothèses!$G$34 -> 139000
A27: Honoraires comptables et audit | B27: =Hypothèses!$B$59*(1+Hypothèses!$B$3)^0 -> 25000 | C27: =Hypothèses!$B$59*(1+Hypothèses!$B$3)^1 -> 25750 | D27: =Hypothèses!$B$59*(1+Hypothèses!$B$3)^2 -> 26522.5 | E27: =Hypothèses!$B$59*(1+Hypothèses!$B$3)^3 -> 27318.175 | F27: =Hypothèses!$B$59*(1+Hypothèses!$B$3)^4 -> 28137.72 | G27: =Hypothèses!$B$59*(1+Hypothèses!$B$3)^5 -> 28981.852
A28: Administration et TI | B28: =B$14*Hypothèses!$B$60 -> 36104.175 | C28: =C$14*Hypothèses!$B$60 -> 53276.91 | D28: =D$14*Hypothèses!$B$60 -> 75996.216 | E28: =E$14*Hypothèses!$B$60 -> 88588.712 | F28: =F$14*Hypothèses!$B$60 -> 96621.983 | G28: =G$14*Hypothèses!$B$60 -> 102855.54
A29: Frais bancaires et de cartes | B29: =B$14*Hypothèses!$B$61 -> 27078.131 | C29: =C$14*Hypothèses!$B$61 -> 39957.682 | D29: =D$14*Hypothèses!$B$61 -> 56997.162 | E29: =E$14*Hypothèses!$B$61 -> 66441.534 | F29: =F$14*Hypothèses!$B$61 -> 72466.487 | G29: =G$14*Hypothèses!$B$61 -> 77141.654
A30: Fournitures | B30: =B$14*Hypothèses!$B$62 -> 45130.219 | C30: =C$14*Hypothèses!$B$62 -> 66596.137 | D30: =D$14*Hypothèses!$B$62 -> 94995.27 | E30: =E$14*Hypothèses!$B$62 -> 110735.89 | F30: =F$14*Hypothèses!$B$62 -> 120777.48 | G30: =G$14*Hypothèses!$B$62 -> 128569.42
A31: Loyers et locations | B31: =Hypothèses!$B$63*1.02^0 -> 42000 | C31: =Hypothèses!$B$63*1.02^1 -> 42840 | D31: =Hypothèses!$B$63*1.02^2 -> 43696.8 | E31: =Hypothèses!$B$63*1.02^3 -> 44570.736 | F31: =Hypothèses!$B$63*1.02^4 -> 45462.151 | G31: =Hypothèses!$B$63*1.02^5 -> 46371.394
A32: Divers et imprévus | B32: =B$14*Hypothèses!$B$64 -> 36104.175 | C32: =C$14*Hypothèses!$B$64 -> 53276.91 | D32: =D$14*Hypothèses!$B$64 -> 75996.216 | E32: =E$14*Hypothèses!$B$64 -> 88588.712 | F32: =F$14*Hypothèses!$B$64 -> 96621.983 | G32: =G$14*Hypothèses!$B$64 -> 102855.54
A33: Total des charges | B33: =SUM(B17:B32) -> 1611861.1 | C33: =SUM(C17:C32) -> 2208259.2 | D33: =SUM(D17:D32) -> 3135510.9 | E33: =SUM(E17:E32) -> 3505360.3 | F33: =SUM(F17:F32) -> 3746304.6 | G33: =SUM(G17:G32) -> 3920276.6
A35: BAIIA | B35: =B14-B33 -> 193347.67 | C35: =C14-C33 -> 455586.26 | D35: =D14-D33 -> 664299.93 | E35: =E14-E33 -> 924075.32 | F35: =F14-F33 -> 1084794.6 | G35: =G14-G33 -> 1222500.3
A36: Marge BAIIA | B36: =B35/B14 -> 0.10710544 | C36: =C35/C14 -> 0.17102579 | D36: =D35/D14 -> 0.17482448 | E36: =E35/E14 -> 0.20862146 | F36: =F35/F14 -> 0.22454406 | G36: =G35/G14 -> 0.23771211
A37: Amortissement comptable (DPA!) | B37: =DPA!B$3 -> 150000 | C37: =DPA!C$3 -> 231757.25 | D37: =DPA!D$3 -> 313514.5 | E37: =DPA!E$3 -> 313514.5 | F37: =DPA!F$3 -> 313514.5 | G37: =DPA!G$3 -> 313514.5
A38: Intérêts (toutes couches ; 2026 : dette existante) | B38: =Investissement!B10*Hypothèses!$B$68 -> 300000 | C38: =Dette!$B$65+Dette!$B$135+Dette!$B$205+Dette!$B$275+Dette!$B$345 -> 470750 | D38: =Dette!$B$66+Dette!$B$136+Dette!$B$206+Dette!$B$276+Dette!$B$346 -> 467600.89 | E38: =Dette!$B$67+Dette!$B$137+Dette!$B$207+Dette!$B$277+Dette!$B$347 -> 459663.27 | F38: =Dette!$B$68+Dette!$B$138+Dette!$B$208+Dette!$B$278+Dette!$B$348 -> 446998.17 | G38: =Dette!$B$69+Dette!$B$139+Dette!$B$209+Dette!$B$279+Dette!$B$349 -> 429413.96
A39: Bénéfice avant impôts | B39: =B35-B37-B38 -> -256652.33 | C39: =C35-C37-C38 -> -246920.99 | D39: =D35-D37-D38 -> -116815.46 | E39: =E35-E37-E38 -> 150897.55 | F39: =F35-F37-F38 -> 324281.93 | G39: =G35-G37-G38 -> 479571.88
A40: Impôts | B40: =IF(B39<=0,0,MIN(B39,500000)*Hypothèses!$B$66+MAX(B39-500000,0)*Hypothèses!$B$67) -> 0 | C40: =IF(C39<=0,0,MIN(C39,500000)*Hypothèses!$B$66+MAX(C39-500000,0)*Hypothèses!$B$67) -> 0 | D40: =IF(D39<=0,0,MIN(D39,500000)*Hypothèses!$B$66+MAX(D39-500000,0)*Hypothèses!$B$67) -> 0 | E40: =IF(E39<=0,0,MIN(E39,500000)*Hypothèses!$B$66+MAX(E39-500000,0)*Hypothèses!$B$67) -> 18409.501 | F40: =IF(F39<=0,0,MIN(F39,500000)*Hypothèses!$B$66+MAX(F39-500000,0)*Hypothèses!$B$67) -> 39562.396 | G40: =IF(G39<=0,0,MIN(G39,500000)*Hypothèses!$B$66+MAX(G39-500000,0)*Hypothèses!$B$67) -> 58507.77
A41: Bénéfice net | B41: =B39-B40 -> -256652.33 | C41: =C39-C40 -> -246920.99 | D41: =D39-D40 -> -116815.46 | E41: =E39-E40 -> 132488.05 | F41: =F39-F40 -> 284719.54 | G41: =G39-G40 -> 421064.11
A43: Service de la dette : prêt senior | B43: =B38 -> 300000 | C43: =Dette!$D$65 -> 385000 | D43: =Dette!$D$66 -> 466474.27 | E43: =Dette!$D$67 -> 466474.27 | F43: =Dette!$D$68 -> 466474.27 | G43: =Dette!$D$69 -> 466474.27
...

Sheet Flux
A1: Flux de trésorerie (méthode indirecte) | B1: 2026 | C1: An 1 | D1: An 2 | E1: An 3 | F1: An 4 | G1: An 5
A2: Bénéfice net | B2: =Résultats!B41 -> -256652.33 | C2: =Résultats!C41 -> -246920.99 | D2: =Résultats!D41 -> -116815.46 | E2: =Résultats!E41 -> 132488.05 | F2: =Résultats!F41 -> 284719.54 | G2: =Résultats!G41 -> 421064.11
A3: Plus : amortissement | B3: =Résultats!B37 -> 150000 | C3: =Résultats!C37 -> 231757.25 | D3: =Résultats!D37 -> 313514.5 | E3: =Résultats!E37 -> 313514.5 | F3: =Résultats!F37 -> 313514.5 | G3: =Résultats!G37 -> 313514.5
A4: Flux d'exploitation | B4: =B2+B3 -> -106652.33 | C4: =C2+C3 -> -15163.735 | D4: =D2+D3 -> 196699.04 | E4: =E2+E3 -> 446002.55 | F4: =F2+F3 -> 598234.04 | G4: =G2+G3 -> 734578.61
A5: Moins : remboursement de capital | B5: =-Résultats!B45 -> 0 | C5: =-Résultats!C45 -> 0 | D5: =-Résultats!D45 -> -101918.78 | E5: =-Résultats!E45 -> -213929.11 | F5: =-Résultats!F45 -> -303895.91 | G5: =-Résultats!G45 -> -321480.12
A6: Moins : immobilisations de maintien | B6: =-Résultats!B46 -> 0 | C6: =-Résultats!C46 -> -53276.91 | D6: =-Résultats!D46 -> -75996.216 | E6: =-Résultats!E46 -> -88588.712 | F6: =-Résultats!F46 -> -96621.983 | G6: =-Résultats!G46 -> -102855.54
A7: Flux disponible | B7: =B4+B5+B6 -> -106652.33 | C7: =C4+C5+C6 -> -68440.645 | D7: =D4+D5+D6 -> 18784.046 | E7: =E4+E5+E6 -> 143484.73 | F7: =F4+F5+F6 -> 197716.14 | G7: =G4+G5+G6 -> 310242.95
A8: Trésorerie cumulée depuis la clôture | B8: =0 -> 0 | C8: =B8+C7 -> -68440.645 | D8: =C8+D7 -> -49656.599 | E8: =D8+E7 -> 93828.126 | F8: =E8+F7 -> 291544.27 | G8: =F8+G7 -> 601787.22

Sheet DPA
A1: Amortissement comptable et DPA | B1: 2026 | C1: An 1 | D1: An 2 | E1: An 3 | F1: An 4 | G1: An 5
A2: Base capitalisée (phase 1a, contingence et honoraires au prorata) | B2: =Investissement!B2+Investissement!B3+Investissement!B4 -> 3270290
A3: Amortissement comptable total (→ Résultats) | B3: =B4+B5 -> 150000 | C3: =C4+C5 -> 231757.25 | D3: =D4+D5 -> 313514.5 | E3: =E4+E5 -> 313514.5 | F3: =F4+F5 -> 313514.5 | G3: =G4+G5 -> 313514.5
A4: Existant | B4: =Hypothèses!$B$65 -> 150000 | C4: =Hypothèses!$B$65 -> 150000 | D4: =Hypothèses!$B$65 -> 150000 | E4: =Hypothèses!$B$65 -> 150000 | F4: =Hypothèses!$B$65 -> 150000 | G4: =Hypothèses!$B$65 -> 150000
A5: Nouveau (linéaire moyen 5 % ; phase 1a mise en service An 1, demi-année) | B5: =0 -> 0 | C5: =$B$2*0.05*0.5 -> 81757.25 | D5: =$B$2*0.05 -> 163514.5 | E5: =$B$2*0.05 -> 163514.5 | F5: =$B$2*0.05 -> 163514.5 | G5: =$B$2*0.05 -> 163514.5
A7: DPA fiscale (solde dégressif, demi-année) — informatif
A8: Catégorie | B8: Taux | C8: Base | D8: DPA An 1 | E8: DPA An 2 | F8: DPA An 3 | G8: DPA An 4 | H8: DPA An 5
A9: Cat. 1 — bâtiments : hôtel, restaurant, villas, chalets | B9: 0.04 | C9: 2058368.4 | D9: 41167.368 | E9: 80688.042 | F9: 77460.52 | G9: 74362.099 | H9: 71387.615
A10: Cat. 8 — équipements : mobilier | B10: 0.2 | C10: 0 | D10: 0 | E10: 0 | F10: 0 | G10: 0 | H10: 0
A11: Cat. 6 / à confirmer — unités d'hébergement préfabriquées sur structure d'acier (Coolbox) | B11: 0.1 | C11: 1154744.7 | D11: 57737.234 | E11: 109700.74 | F11: 98730.67 | G11: 88857.603 | H11: 79971.843
A12: Cat. 17 — aménagements de surface : conversion de terrains saisonniers | B12: 0.08 | C12: 57176.9 | D12: 2287.076 | E12: 4391.186 | F12: 4039.8911 | G12: 3716.6998 | H12: 3419.3638
A13: Frais de financement (déductibles sur 5 ans) | B13: 0.2 | C13: 125000 | D13: 25000 | E13: 25000 | F13: 25000 | G13: 25000 | H13: 25000

Sheet Bilan
A1: Bilan pro forma au 31 décembre | B1: An 1 | C1: An 2 | D1: An 3 | E1: An 4 | F1: An 5
A2: Immobilisations existantes au coût déclaré (hyp.) | B2: 11915000
A3: Amortissement cumulé estimé au 31-12-2026 (hyp.) | B3: 3000000
A5: ACTIF
A6: Encaisse | B6: =Investissement!B9+Investissement!B7+Flux!C8 -> 414796.36 | C6: =Investissement!B9+Investissement!B7+Flux!D8 -> 433580.4 | D6: =Investissement!B9+Investissement!B7+Flux!E8 -> 577065.13 | E6: =Investissement!B9+Investissement!B7+Flux!F8 -> 774781.27 | F6: =Investissement!B9+Investissement!B7+Flux!G8 -> 1085024.2
A7: Immobilisations existantes, nettes | B7: =$B$2-$B$3-Hypothèses!$B$65*1 -> 8765000 | C7: =$B$2-$B$3-Hypothèses!$B$65*2 -> 8615000 | D7: =$B$2-$B$3-Hypothèses!$B$65*3 -> 8465000 | E7: =$B$2-$B$3-Hypothèses!$B$65*4 -> 8315000 | F7: =$B$2-$B$3-Hypothèses!$B$65*5 -> 8165000
A8: Nouvelles immobilisations, nettes | B8: =DPA!$B$2+SUM(Résultats!$C$46:C$46)-SUM(DPA!$C$5:C$5) -> 3241809.7 | C8: =DPA!$B$2+SUM(Résultats!$C$46:D$46)-SUM(DPA!$C$5:D$5) -> 3154291.4 | D8: =DPA!$B$2+SUM(Résultats!$C$46:E$46)-SUM(DPA!$C$5:E$5) -> 3079365.6 | E8: =DPA!$B$2+SUM(Résultats!$C$46:F$46)-SUM(DPA!$C$5:F$5) -> 3012473.1 | F8: =DPA!$B$2+SUM(Résultats!$C$46:G$46)-SUM(DPA!$C$5:G$5) -> 2951814.1
A9: Frais reportés | B9: =(Investissement!B5+Investissement!B6+Investissement!B8)*(1-1/5) -> 342000 | C9: =(Investissement!B5+Investissement!B6+Investissement!B8)*(1-2/5) -> 256500 | D9: =(Investissement!B5+Investissement!B6+Investissement!B8)*(1-3/5) -> 171000 | E9: =(Investissement!B5+Investissement!B6+Investissement!B8)*(1-4/5) -> 85500 | F9: =(Investissement!B5+Investissement!B6+Investissement!B8)*(1-5/5) -> 0
A10: Total de l'actif | B10: =SUM(B6:B9) -> 12763606 | C10: =SUM(C6:C9) -> 12459372 | D10: =SUM(D6:D9) -> 12292431 | E10: =SUM(E6:E9) -> 12187754 | F10: =SUM(F6:F9) -> 12201838
A11: PASSIF
A12: Dette totale (toutes couches) | B12: =Dette!$E$65+Dette!$E$135+Dette!$E$205+Dette!$E$275+Dette!$E$345 -> 7085000 | C12: =Dette!$E$66+Dette!$E$136+Dette!$E$206+Dette!$E$276+Dette!$E$346 -> 6983081.2 | D12: =Dette!$E$67+Dette!$E$137+Dette!$E$207+Dette!$E$277+Dette!$E$347 -> 6769152.1 | E12: =Dette!$E$68+Dette!$E$138+Dette!$E$208+Dette!$E$278+Dette!$E$348 -> 6465256.2 | F12: =Dette!$E$69+Dette!$E$139+Dette!$E$209+Dette!$E$279+Dette!$E$349 -> 6143776.1
A13: AVOIR
A14: Avoir à l'ouverture | B14: =$B$2-$B$3+Investissement!B9+Investissement!B7+(Investissement!B5+Investissement!B6+Investissement!B8)+DPA!$B$2-SUM(Investissement!B14:B18) -> 6011027 | C14: =$B$2-$B$3+Investissement!B9+Investissement!B7+(Investissement!B5+Investissement!B6+Investissement!B8)+DPA!$B$2-SUM(Investissement!B14:B18) -> 6011027 | D14: =$B$2-$B$3+Investissement!B9+Investissement!B7+(Investissement!B5+Investissement!B6+Investissement!B8)+DPA!$B$2-SUM(Investissement!B14:B18) -> 6011027 | E14: =$B$2-$B$3+Investissement!B9+Investissement!B7+(Investissement!B5+Investissement!B6+Investissement!B8)+DPA!$B$2-SUM(Investissement!B14:B18) -> 6011027 | F14: =$B$2-$B$3+Investissement!B9+Investissement!B7+(Investissement!B5+Investissement!B6+Investissement!B8)+DPA!$B$2-SUM(Investissement!B14:B18) -> 6011027
A15: Bénéfices non répartis cumulés (nets de l'amortissement des frais reportés) | B15: =SUM(Résultats!$C$41:C$41)-(Investissement!B5+Investissement!B6+Investissement!B8)*1/5 -> -332420.99 | C15: =SUM(Résultats!$C$41:D$41)-(Investissement!B5+Investissement!B6+Investissement!B8)*2/5 -> -534736.45 | D15: =SUM(Résultats!$C$41:E$41)-(Investissement!B5+Investissement!B6+Investissement!B8)*3/5 -> -487748.4 | E15: =SUM(Résultats!$C$41:F$41)-(Investissement!B5+Investissement!B6+Investissement!B8)*4/5 -> -288528.87 | F15: =SUM(Résultats!$C$41:G$41)-(Investissement!B5+Investissement!B6+Investissement!B8)*5/5 -> 47035.248
A16: Total de l'avoir | B16: =B14+B15 -> 5678606 | C16: =C14+C15 -> 5476290.6 | D16: =D14+D15 -> 5523278.6 | E16: =E14+E15 -> 5722498.1 | F16: =F14+F15 -> 6058062.2
A17: Total passif + avoir | B17: =B12+B16 -> 12763606 | C17: =C12+C16 -> 12459372 | D17: =D12+D16 -> 12292431 | E17: =E12+E16 -> 12187754 | F17: =F12+F16 -> 12201838
A18: Écart (doit être 0) | B18: =B10-B17 -> 0 | C18: =C10-C17 -> 0 | D18: =D10-D17 -> 0 | E18: =E10-E17 -> 0 | F18: =F10-F17 -> 0

Sheet Ratios
A1: Ratio | B1: An 1 | C1: An 2 | D1: An 3 | E1: An 4 | F1: An 5
A2: Couverture du prêt senior (BAIIA / service senior) | B2: =Résultats!C35/Résultats!C43 -> 1.1833409 | C2: =Résultats!D35/Résultats!D43 -> 1.424087 | D2: =Résultats!E35/Résultats!E43 -> 1.9809781 | E2: =Résultats!F35/Résultats!F43 -> 2.3255186 | F2: =Résultats!G35/Résultats!G43 -> 2.6207241
A3: Couverture toutes couches (BAIIA / service total) | B3: =Résultats!C35/Résultats!C44 -> 0.96778814 | C3: =Résultats!D35/Résultats!D44 -> 1.1664214 | D3: =Résultats!E35/Résultats!E44 -> 1.3718613 | E3: =Résultats!F35/Résultats!F44 -> 1.4446706 | F3: =Résultats!G35/Résultats!G44 -> 1.6280596
A4: Couverture bancaire ((BAIIA − impôts − maintien) / service total) | B4: =(Résultats!C35-Résultats!C40-Résultats!C46)/Résultats!C44 -> 0.85461361 | C4: =(Résultats!D35-Résultats!D40-Résultats!D46)/Résultats!D44 -> 1.0329823 | D4: =(Résultats!E35-Résultats!E40-Résultats!E46)/Résultats!E44 -> 1.2130142 | E4: =(Résultats!F35-Résultats!F40-Résultats!F46)/Résultats!F44 -> 1.2633076 | F4: =(Résultats!G35-Résultats!G40-Résultats!G46)/Résultats!G44 -> 1.4131647
A5: Couverture des intérêts | B5: =Résultats!C35/Résultats!C38 -> 0.96778814 | C5: =Résultats!D35/Résultats!D38 -> 1.4206558 | D5: =Résultats!E35/Résultats!E38 -> 2.010331 | E5: =Résultats!F35/Résultats!F38 -> 2.4268435 | F5: =Résultats!G35/Résultats!G38 -> 2.8469041
A6: Dette totale / BAIIA | B6: =Bilan!B12/Résultats!C35 -> 15.551391 | C6: =Bilan!C12/Résultats!D35 -> 10.51194 | D6: =Bilan!D12/Résultats!E35 -> 7.3253251 | E6: =Bilan!E12/Résultats!F35 -> 5.9598897 | F6: =Bilan!F12/Résultats!G35 -> 5.0255823
A7: Dette / avoir | B7: =Bilan!B12/Bilan!B16 -> 1.2476654 | C7: =Bilan!C12/Bilan!C16 -> 1.2751481 | D7: =Bilan!D12/Bilan!D16 -> 1.2255677 | E7: =Bilan!E12/Bilan!E16 -> 1.1297961 | F7: =Bilan!F12/Bilan!F16 -> 1.0141487
A8: Marge BAIIA | B8: =Résultats!C35/Résultats!C14 -> 0.17102579 | C8: =Résultats!D35/Résultats!D14 -> 0.17482448 | D8: =Résultats!E35/Résultats!E14 -> 0.20862146 | E8: =Résultats!F35/Résultats!F14 -> 0.22454406 | F8: =Résultats!G35/Résultats!G14 -> 0.23771211
A9: Marge nette | B9: =Résultats!C41/Résultats!C14 -> -0.092693434 | C9: =Résultats!D41/Résultats!D14 -> -0.030742442 | D9: =Résultats!E41/Résultats!E14 -> 0.029910819 | E9: =Résultats!F41/Résultats!F14 -> 0.058934732 | F9: =Résultats!G41/Résultats!G14 -> 0.081874855

Sheet Sensibilité
A1: Sensibilité : modifier « SCÉNARIO : facteur sur les revenus » dans Hypothèses (1 = base, 0,9 = −10 %, etc.) ; les charges variables suivent selon leur part variable. Tableau statique ci-dessous produit par le modèle Python pour référence.
A3: Scénario | B3: Toutes couches An 2 | C3: An 3 | D3: An 5 | E3: Bancaire An 3 | F3: Bancaire An 5
A4: Scénario de base | B4: 1.17 | C4: 1.37 | D4: 1.63 | E4: 1.21 | F4: 1.41
A5: Revenus −10 % | B5: 0.76 | C5: 0.97 | D5: 1.21 | E5: 0.85 | F5: 1.06
A6: Revenus −15 % | B6: 0.56 | C6: 0.77 | D6: 1 | E6: 0.66 | F6: 0.88
A7: Revenus −20 % | B7: 0.36 | C7: 0.57 | D7: 0.79 | E7: 0.47 | F7: 0.68
A8: Revenus d'hiver −50 % | B8: 0.93 | C8: 1.12 | D8: 1.36 | E8: 1 | F8: 1.18
A9: Restauration −50 % (permis d'alcool retardé, achalandage) | B9: 0.94 | C9: 1.09 | D9: 1.31 | E9: 0.97 | F9: 1.14
A10: Taux senior 8 % (25 ans) | B10: 1.15 | C10: 1.29 | D10: 1.54 | E10: 1.14 | F10: 1.33
A11: Taux senior 9 % (25 ans) | B11: 1.06 | C11: 1.21 | D11: 1.46 | E11: 1.07 | F11: 1.26
A12: Amortissement senior 20 ans (7 %) | B12: 1.2 | C12: 1.29 | D12: 1.54 | E12: 1.13 | F12: 1.33
A14: Part variable calculée (An 3) | B14: 0.49785294
